Internal Server Error: /
Traceback (most recent call last):
  File "E:\Anaconda\envs\python\lib\site-packages\django\core\handlers\exception.py", line 55, in inner
    response = get_response(request)
  File "E:\Anaconda\envs\python\lib\site-packages\django\core\handlers\base.py", line 197, in _get_response
    response = wrapped_callback(request, *callback_args, **callback_kwargs)
  File "C:\Users\amank\OneDrive\Desktop\chatpdfproject\chatwithpdf\views.py", line 103, in index
    return redirect('ask_page')
  File "E:\Anaconda\envs\python\lib\site-packages\django\shortcuts.py", line 48, in redirect
    return redirect_class(resolve_url(to, *args, **kwargs))
  File "E:\Anaconda\envs\python\lib\site-packages\django\shortcuts.py", line 145, in resolve_url
    return reverse(to, args=args, kwargs=kwargs)
  File "E:\Anaconda\envs\python\lib\site-packages\django\urls\base.py", line 88, in reverse
    return resolver._reverse_with_prefix(view, prefix, *args, **kwargs)
  File "E:\Anaconda\envs\python\lib\site-packages\django\urls\resolvers.py", line 828, in _reverse_with_prefix
    raise NoReverseMatch(msg)
django.urls.exceptions.NoReverseMatch: Reverse for 'ask_page' not found. 'ask_page' is not a valid view function or pattern name.
"GET / HTTP/1.1" 500 86245
Internal Server Error: /api/ask/
Traceback (most recent call last):
  File "E:\Anaconda\envs\python\lib\site-packages\django\core\handlers\exception.py", line 55, in inner
    response = get_response(request)
  File "E:\Anaconda\envs\python\lib\site-packages\django\core\handlers\base.py", line 197, in _get_response
    response = wrapped_callback(request, *callback_args, **callback_kwargs)
  File "E:\Anaconda\envs\python\lib\site-packages\django\views\decorators\csrf.py", line 56, in wrapper_view
    return view_func(*args, **kwargs)
  File "C:\Users\amank\OneDrive\Desktop\chatpdfproject\chatwithpdf\views.py", line 117, in ask
    result = process_user_question(user_question, vectordb)
TypeError: process_user_question() missing 1 required positional argument: 'request'
"POST /api/ask/ HTTP/1.1" 500 72231
Internal Server Error: /api/ask/
Traceback (most recent call last):
  File "E:\Anaconda\envs\python\lib\site-packages\django\core\handlers\exception.py", line 55, in inner
    response = get_response(request)
  File "E:\Anaconda\envs\python\lib\site-packages\django\core\handlers\base.py", line 197, in _get_response
    response = wrapped_callback(request, *callback_args, **callback_kwargs)
  File "E:\Anaconda\envs\python\lib\site-packages\django\views\decorators\csrf.py", line 56, in wrapper_view
    return view_func(*args, **kwargs)
  File "C:\Users\amank\OneDrive\Desktop\chatpdfproject\chatwithpdf\views.py", line 117, in ask
    result = process_user_question(user_question, vectordb)
TypeError: process_user_question() missing 1 required positional argument: 'request'
"POST /api/ask/ HTTP/1.1" 500 72231
Internal Server Error: /register/
Traceback (most recent call last):
  File "E:\Anaconda\envs\python\lib\site-packages\django\core\handlers\exception.py", line 55, in inner
    response = get_response(request)
  File "E:\Anaconda\envs\python\lib\site-packages\django\core\handlers\base.py", line 197, in _get_response
    response = wrapped_callback(request, *callback_args, **callback_kwargs)
  File "C:\Users\amank\OneDrive\Desktop\chatpdfproject\chatwithpdf\views.py", line 179, in register
    return render(request, 'registration/register.html', {'form': form})
  File "E:\Anaconda\envs\python\lib\site-packages\django\shortcuts.py", line 24, in render
    content = loader.render_to_string(template_name, context, request, using=using)
  File "E:\Anaconda\envs\python\lib\site-packages\django\template\loader.py", line 61, in render_to_string
    template = get_template(template_name, using=using)
  File "E:\Anaconda\envs\python\lib\site-packages\django\template\loader.py", line 19, in get_template
    raise TemplateDoesNotExist(template_name, chain=chain)
django.template.exceptions.TemplateDoesNotExist: registration/register.html
"GET /register/ HTTP/1.1" 500 83583
Internal Server Error: /
Traceback (most recent call last):
  File "E:\Anaconda\envs\python\lib\site-packages\django\core\handlers\exception.py", line 55, in inner
    response = get_response(request)
  File "E:\Anaconda\envs\python\lib\site-packages\django\core\handlers\base.py", line 220, in _get_response
    response = response.render()
  File "E:\Anaconda\envs\python\lib\site-packages\django\template\response.py", line 114, in render
    self.content = self.rendered_content
  File "E:\Anaconda\envs\python\lib\site-packages\django\template\response.py", line 92, in rendered_content
    return template.render(context, self._request)
  File "E:\Anaconda\envs\python\lib\site-packages\django\template\backends\django.py", line 61, in render
    return self.template.render(context)
  File "E:\Anaconda\envs\python\lib\site-packages\django\template\base.py", line 175, in render
    return self._render(context)
  File "E:\Anaconda\envs\python\lib\site-packages\django\template\base.py", line 167, in _render
    return self.nodelist.render(context)
  File "E:\Anaconda\envs\python\lib\site-packages\django\template\base.py", line 1005, in render
    return SafeString("".join([node.render_annotated(context) for node in self]))
  File "E:\Anaconda\envs\python\lib\site-packages\django\template\base.py", line 1005, in <listcomp>
    return SafeString("".join([node.render_annotated(context) for node in self]))
  File "E:\Anaconda\envs\python\lib\site-packages\django\template\base.py", line 966, in render_annotated
    return self.render(context)
  File "E:\Anaconda\envs\python\lib\site-packages\django\template\loader_tags.py", line 157, in render
    return compiled_parent._render(context)
  File "E:\Anaconda\envs\python\lib\site-packages\django\template\base.py", line 167, in _render
    return self.nodelist.render(context)
  File "E:\Anaconda\envs\python\lib\site-packages\django\template\base.py", line 1005, in render
    return SafeString("".join([node.render_annotated(context) for node in self]))
  File "E:\Anaconda\envs\python\lib\site-packages\django\template\base.py", line 1005, in <listcomp>
    return SafeString("".join([node.render_annotated(context) for node in self]))
  File "E:\Anaconda\envs\python\lib\site-packages\django\template\base.py", line 966, in render_annotated
    return self.render(context)
  File "E:\Anaconda\envs\python\lib\site-packages\django\template\defaulttags.py", line 321, in render
    return nodelist.render(context)
  File "E:\Anaconda\envs\python\lib\site-packages\django\template\base.py", line 1005, in render
    return SafeString("".join([node.render_annotated(context) for node in self]))
  File "E:\Anaconda\envs\python\lib\site-packages\django\template\base.py", line 1005, in <listcomp>
    return SafeString("".join([node.render_annotated(context) for node in self]))
  File "E:\Anaconda\envs\python\lib\site-packages\django\template\base.py", line 966, in render_annotated
    return self.render(context)
  File "E:\Anaconda\envs\python\lib\site-packages\django\template\defaulttags.py", line 471, in render
    url = reverse(view_name, args=args, kwargs=kwargs, current_app=current_app)
  File "E:\Anaconda\envs\python\lib\site-packages\django\urls\base.py", line 88, in reverse
    return resolver._reverse_with_prefix(view, prefix, *args, **kwargs)
  File "E:\Anaconda\envs\python\lib\site-packages\django\urls\resolvers.py", line 828, in _reverse_with_prefix
    raise NoReverseMatch(msg)
django.urls.exceptions.NoReverseMatch: Reverse for 'download_csv_page' not found. 'download_csv_page' is not a valid view function or pattern name.
"GET / HTTP/1.1" 500 161958
Internal Server Error: /api/ask/
Traceback (most recent call last):
  File "E:\Anaconda\envs\python\lib\site-packages\django\core\handlers\exception.py", line 55, in inner
    response = get_response(request)
  File "E:\Anaconda\envs\python\lib\site-packages\django\core\handlers\base.py", line 197, in _get_response
    response = wrapped_callback(request, *callback_args, **callback_kwargs)
  File "E:\Anaconda\envs\python\lib\site-packages\django\views\decorators\csrf.py", line 56, in wrapper_view
    return view_func(*args, **kwargs)
  File "C:\Users\amank\OneDrive\Desktop\chat pdf django user login\chatwithpdf\views.py", line 123, in ask
    result = process_user_question(user_question, vectordb)
TypeError: process_user_question() missing 1 required positional argument: 'vectordb'
"POST /api/ask/ HTTP/1.1" 500 72738
Internal Server Error: /api/ask/
Traceback (most recent call last):
  File "E:\Anaconda\envs\python\lib\site-packages\django\core\handlers\exception.py", line 55, in inner
    response = get_response(request)
  File "E:\Anaconda\envs\python\lib\site-packages\django\core\handlers\base.py", line 197, in _get_response
    response = wrapped_callback(request, *callback_args, **callback_kwargs)
  File "E:\Anaconda\envs\python\lib\site-packages\django\views\decorators\csrf.py", line 56, in wrapper_view
    return view_func(*args, **kwargs)
  File "C:\Users\amank\OneDrive\Desktop\chat pdf django user login\chatwithpdf\views.py", line 123, in ask
    result = process_user_question(user_question, vectordb)
TypeError: process_user_question() missing 1 required positional argument: 'vectordb'
"POST /api/ask/ HTTP/1.1" 500 72738
Internal Server Error: /api/ask/
Traceback (most recent call last):
  File "E:\Anaconda\envs\python\lib\site-packages\django\core\handlers\exception.py", line 55, in inner
    response = get_response(request)
  File "E:\Anaconda\envs\python\lib\site-packages\django\core\handlers\base.py", line 197, in _get_response
    response = wrapped_callback(request, *callback_args, **callback_kwargs)
  File "E:\Anaconda\envs\python\lib\site-packages\django\views\decorators\csrf.py", line 56, in wrapper_view
    return view_func(*args, **kwargs)
  File "C:\Users\amank\OneDrive\Desktop\chat pdf django user login\chatwithpdf\views.py", line 124, in ask
    result = process_user_question(user_question, vectordb)
  File "E:\Anaconda\envs\python\lib\site-packages\django\contrib\auth\decorators.py", line 22, in _wrapper_view
    if test_func(request.user):
AttributeError: 'str' object has no attribute 'user'
"POST /api/ask/ HTTP/1.1" 500 77599
Internal Server Error: /api/ask/
Traceback (most recent call last):
  File "E:\Anaconda\envs\python\lib\site-packages\django\core\handlers\exception.py", line 55, in inner
    response = get_response(request)
  File "E:\Anaconda\envs\python\lib\site-packages\django\core\handlers\base.py", line 197, in _get_response
    response = wrapped_callback(request, *callback_args, **callback_kwargs)
  File "E:\Anaconda\envs\python\lib\site-packages\django\views\decorators\csrf.py", line 56, in wrapper_view
    return view_func(*args, **kwargs)
  File "C:\Users\amank\OneDrive\Desktop\chat pdf django user login\chatwithpdf\views.py", line 124, in ask
    result = process_user_question(user_question, vectordb)
  File "E:\Anaconda\envs\python\lib\site-packages\django\contrib\auth\decorators.py", line 22, in _wrapper_view
    if test_func(request.user):
AttributeError: 'str' object has no attribute 'user'
"POST /api/ask/ HTTP/1.1" 500 77599
Invalid HTTP_HOST header: '127.0.0.1:8000'. You may need to add '127.0.0.1' to ALLOWED_HOSTS.
Traceback (most recent call last):
  File "E:\Anaconda\envs\python\lib\site-packages\django\core\handlers\exception.py", line 55, in inner
    response = get_response(request)
  File "E:\Anaconda\envs\python\lib\site-packages\django\utils\deprecation.py", line 133, in __call__
    response = self.process_request(request)
  File "E:\Anaconda\envs\python\lib\site-packages\django\middleware\common.py", line 48, in process_request
    host = request.get_host()
  File "E:\Anaconda\envs\python\lib\site-packages\django\http\request.py", line 150, in get_host
    raise DisallowedHost(msg)
django.core.exceptions.DisallowedHost: Invalid HTTP_HOST header: '127.0.0.1:8000'. You may need to add '127.0.0.1' to ALLOWED_HOSTS.
Invalid HTTP_HOST header: '127.0.0.1:8000'. You may need to add '127.0.0.1' to ALLOWED_HOSTS.
Traceback (most recent call last):
  File "E:\Anaconda\envs\python\lib\site-packages\django\core\handlers\exception.py", line 55, in inner
    response = get_response(request)
  File "E:\Anaconda\envs\python\lib\site-packages\django\utils\deprecation.py", line 133, in __call__
    response = self.process_request(request)
  File "E:\Anaconda\envs\python\lib\site-packages\django\middleware\common.py", line 48, in process_request
    host = request.get_host()
  File "E:\Anaconda\envs\python\lib\site-packages\django\http\request.py", line 150, in get_host
    raise DisallowedHost(msg)
django.core.exceptions.DisallowedHost: Invalid HTTP_HOST header: '127.0.0.1:8000'. You may need to add '127.0.0.1' to ALLOWED_HOSTS.
Invalid HTTP_HOST header: '127.0.0.1:8000'. You may need to add '127.0.0.1' to ALLOWED_HOSTS.
Traceback (most recent call last):
  File "E:\Anaconda\envs\python\lib\site-packages\django\core\handlers\exception.py", line 55, in inner
    response = get_response(request)
  File "E:\Anaconda\envs\python\lib\site-packages\django\utils\deprecation.py", line 133, in __call__
    response = self.process_request(request)
  File "E:\Anaconda\envs\python\lib\site-packages\django\middleware\common.py", line 48, in process_request
    host = request.get_host()
  File "E:\Anaconda\envs\python\lib\site-packages\django\http\request.py", line 150, in get_host
    raise DisallowedHost(msg)
django.core.exceptions.DisallowedHost: Invalid HTTP_HOST header: '127.0.0.1:8000'. You may need to add '127.0.0.1' to ALLOWED_HOSTS.
Invalid HTTP_HOST header: '127.0.0.1:8000'. You may need to add '127.0.0.1' to ALLOWED_HOSTS.
Traceback (most recent call last):
  File "E:\Anaconda\envs\python\lib\site-packages\django\core\handlers\exception.py", line 55, in inner
    response = get_response(request)
  File "E:\Anaconda\envs\python\lib\site-packages\django\utils\deprecation.py", line 133, in __call__
    response = self.process_request(request)
  File "E:\Anaconda\envs\python\lib\site-packages\django\middleware\common.py", line 48, in process_request
    host = request.get_host()
  File "E:\Anaconda\envs\python\lib\site-packages\django\http\request.py", line 150, in get_host
    raise DisallowedHost(msg)
django.core.exceptions.DisallowedHost: Invalid HTTP_HOST header: '127.0.0.1:8000'. You may need to add '127.0.0.1' to ALLOWED_HOSTS.
Invalid HTTP_HOST header: '127.0.0.1:8000'. You may need to add '127.0.0.1' to ALLOWED_HOSTS.
Traceback (most recent call last):
  File "E:\Anaconda\envs\python\lib\site-packages\django\core\handlers\exception.py", line 55, in inner
    response = get_response(request)
  File "E:\Anaconda\envs\python\lib\site-packages\django\utils\deprecation.py", line 133, in __call__
    response = self.process_request(request)
  File "E:\Anaconda\envs\python\lib\site-packages\django\middleware\common.py", line 48, in process_request
    host = request.get_host()
  File "E:\Anaconda\envs\python\lib\site-packages\django\http\request.py", line 150, in get_host
    raise DisallowedHost(msg)
django.core.exceptions.DisallowedHost: Invalid HTTP_HOST header: '127.0.0.1:8000'. You may need to add '127.0.0.1' to ALLOWED_HOSTS.
